Workbook

Sheet Resumen
A1: Proyecciones climáticas CMIP6 para el Meta (Colombia)
A2: Fuente: Copernicus Climate Data Store, dataset projections-cmip6. Ensamble de 5 modelos, cambio respecto a 1995-2014.
A4: Hallazgos principales (se actualizan con las tablas)
A5: ="Temperatura, largo plazo (2081-2100): "&IF(Temperatura!H7>=0,"+","")&ROUND(Temperatura!H7,1)&" °C en SSP1-2.6, "&IF(Temperatura!H10>=0,"+","")&ROUND(Temperatura!H10,1)&" °C en SSP2-4.5 y "&IF(Temperatura!H13>=0,"+","")&ROUND(Temperatura!H13,1)&" °C en SSP5-8.5." -> Temperatura, largo plazo (2081-2100): +1,1 °C en SSP1-2.6, +2,1 °C en SSP2-4.5 y +4,6 °C en SSP5-8.5.
A6: ="Temperatura, corto plazo (2021-2040): entre "&IF(Temperatura!H5>=0,"+","")&ROUND(Temperatura!H5,1)&" y "&IF(Temperatura!H11>=0,"+","")&ROUND(Temperatura!H11,1)&" °C; los escenarios casi no se separan hasta ~2050." -> Temperatura, corto plazo (2021-2040): entre +0,7 y +0,9 °C; los escenarios casi no se separan hasta ~2050.
A7: ="Precipitación, largo plazo: "&IF(Precipitación!H7>=0,"+","")&ROUND(Precipitación!H7,1)&" % (SSP1-2.6), "&IF(Precipitación!H10>=0,"+","")&ROUND(Precipitación!H10,1)&" % (SSP2-4.5) y "&IF(Precipitación!H13>=0,"+","")&ROUND(Precipitación!H13,1)&" % (SSP5-8.5)." -> Precipitación, largo plazo: +2,1 % (SSP1-2.6), +0,4 % (SSP2-4.5) y -7,7 % (SSP5-8.5).
A8: ="Precipitación: "&IF(COUNTIF(Precipitación!M5:M13,"Sí")=0,"ninguna de las 9 combinaciones",COUNTIF(Precipitación!M5:M13,"Sí")&" de 9 combinaciones")&" tiene un cambio medio mayor que la dispersión entre modelos (ver columna final de la hoja Precipitación)." -> Precipitación: ninguna de las 9 combinaciones tiene un cambio medio mayor que la dispersión entre modelos (ver columna final de la hoja Precipitación).
A11: Tabla 1. Cambio de temperatura media (°C) respecto a 1995-2014
A12: Plazo | B12: SSP1-2.6 (bajas) | C12: SSP2-4.5 (medias) | D12: SSP5-8.5 (altas)
A13: Corto 2021-2040 | B13: =Temperatura!H5 -> 0.73392 | C13: =Temperatura!H8 -> 0.74474 | D13: =Temperatura!H11 -> 0.89206
A14: Mediano 2041-2060 | B14: =Temperatura!H6 -> 1.06212 | C14: =Temperatura!H9 -> 1.38682 | D14: =Temperatura!H12 -> 1.89136
A15: Largo 2081-2100 | B15: =Temperatura!H7 -> 1.06648 | C15: =Temperatura!H10 -> 2.13202 | D15: =Temperatura!H13 -> 4.57432
A18: Tabla 2. Cambio de precipitación media (%) respecto a 1995-2014
A19: Plazo | B19: SSP1-2.6 (bajas) | C19: SSP2-4.5 (medias) | D19: SSP5-8.5 (altas)
A20: Corto 2021-2040 | B20: =Precipitación!H5 -> 0.70086 | C20: =Precipitación!H8 -> 0.31434 | D20: =Precipitación!H11 -> -1.38596
A21: Mediano 2041-2060 | B21: =Precipitación!H6 -> 2.00764 | C21: =Precipitación!H9 -> 0.02982 | D21: =Precipitación!H12 -> -4.02746
A22: Largo 2081-2100 | B22: =Precipitación!H7 -> 2.10228 | C22: =Precipitación!H10 -> 0.44606 | D22: =Precipitación!H13 -> -7.6685

Sheet Temperatura
A1: Temperatura: cambio respecto a 1995-2014 por modelo (°C)
A2: Azul = valor calculado a partir de los NetCDF (entrada). Negro = fórmula. Ventana de plazo menos línea base del mismo modelo.
A4: Escenario | B4: Plazo | C4: ACCESS-CM2 | D4: GFDL-ESM4 | E4: MPI-ESM1-2-LR | F4: MRI-ESM2-0 | G4: NorESM2-MM | H4: Media ensamble | I4: Mínimo | J4: Máximo | K4: Desv. est. | L4: Modelos con aumento | M4: ¿Señal > dispersión?
A5: SSP1-2.6 (bajas) | B5: Corto 2021-2040 | C5: 1.1657 | D5: 0.4418 | E5: 0.5751 | F5: 0.6789 | G5: 0.8081 | H5: =AVERAGE(C5:G5) -> 0.73392 | I5: =MIN(C5:G5) -> 0.4418 | J5: =MAX(C5:G5) -> 1.1657 | K5: =STDEV(C5:G5) -> 0.2763701 | L5: =COUNTIF(C5:G5,">0")&" de "&COUNT(C5:G5) -> 5 de 5 | M5: =IF(ABS(H5)>K5,"Sí","No: dentro de la dispersión") -> Sí
A6: SSP1-2.6 (bajas) | B6: Mediano 2041-2060 | C6: 1.7283 | D6: 0.8062 | E6: 0.9133 | F6: 0.9022 | G6: 0.9606 | H6: =AVERAGE(C6:G6) -> 1.06212 | I6: =MIN(C6:G6) -> 0.8062 | J6: =MAX(C6:G6) -> 1.7283 | K6: =STDEV(C6:G6) -> 0.37660289 | L6: =COUNTIF(C6:G6,">0")&" de "&COUNT(C6:G6) -> 5 de 5 | M6: =IF(ABS(H6)>K6,"Sí","No: dentro de la dispersión") -> Sí
A7: SSP1-2.6 (bajas) | B7: Largo 2081-2100 | C7: 1.8714 | D7: 0.6801 | E7: 0.5926 | F7: 1.0524 | G7: 1.1359 | H7: =AVERAGE(C7:G7) -> 1.06648 | I7: =MIN(C7:G7) -> 0.5926 | J7: =MAX(C7:G7) -> 1.8714 | K7: =STDEV(C7:G7) -> 0.50664715 | L7: =COUNTIF(C7:G7,">0")&" de "&COUNT(C7:G7) -> 5 de 5 | M7: =IF(ABS(H7)>K7,"Sí","No: dentro de la dispersión") -> Sí
A8: SSP2-4.5 (medias) | B8: Corto 2021-2040 | C8: 1.0824 | D8: 0.5608 | E8: 0.6094 | F8: 0.7848 | G8: 0.6863 | H8: =AVERAGE(C8:G8) -> 0.74474 | I8: =MIN(C8:G8) -> 0.5608 | J8: =MAX(C8:G8) -> 1.0824 | K8: =STDEV(C8:G8) -> 0.20687264 | L8: =COUNTIF(C8:G8,">0")&" de "&COUNT(C8:G8) -> 5 de 5 | M8: =IF(ABS(H8)>K8,"Sí","No: dentro de la dispersión") -> Sí
A9: SSP2-4.5 (medias) | B9: Mediano 2041-2060 | C9: 2.1354 | D9: 1.0035 | E9: 1.1853 | F9: 1.2008 | G9: 1.4091 | H9: =AVERAGE(C9:G9) -> 1.38682 | I9: =MIN(C9:G9) -> 1.0035 | J9: =MAX(C9:G9) -> 2.1354 | K9: =STDEV(C9:G9) -> 0.44244107 | L9: =COUNTIF(C9:G9,">0")&" de "&COUNT(C9:G9) -> 5 de 5 | M9: =IF(ABS(H9)>K9,"Sí","No: dentro de la dispersión") -> Sí
A10: SSP2-4.5 (medias) | B10: Largo 2081-2100 | C10: 3.187 | D10: 1.5774 | E10: 2.0132 | F10: 1.9764 | G10: 1.9061 | H10: =AVERAGE(C10:G10) -> 2.13202 | I10: =MIN(C10:G10) -> 1.5774 | J10: =MAX(C10:G10) -> 3.187 | K10: =STDEV(C10:G10) -> 0.61440251 | L10: =COUNTIF(C10:G10,">0")&" de "&COUNT(C10:G10) -> 5 de 5 | M10: =IF(ABS(H10)>K10,"Sí","No: dentro de la dispersión") -> Sí
A11: SSP5-8.5 (altas) | B11: Corto 2021-2040 | C11: 1.1681 | D11: 0.5839 | E11: 0.9667 | F11: 0.871 | G11: 0.8706 | H11: =AVERAGE(C11:G11) -> 0.89206 | I11: =MIN(C11:G11) -> 0.5839 | J11: =MAX(C11:G11) -> 1.1681 | K11: =STDEV(C11:G11) -> 0.21073434 | L11: =COUNTIF(C11:G11,">0")&" de "&COUNT(C11:G11) -> 5 de 5 | M11: =IF(ABS(H11)>K11,"Sí","No: dentro de la dispersión") -> Sí
A12: SSP5-8.5 (altas) | B12: Mediano 2041-2060 | C12: 2.5421 | D12: 1.457 | E12: 2.031 | F12: 1.7283 | G12: 1.6984 | H12: =AVERAGE(C12:G12) -> 1.89136 | I12: =MIN(C12:G12) -> 1.457 | J12: =MAX(C12:G12) -> 2.5421 | K12: =STDEV(C12:G12) -> 0.41696901 | L12: =COUNTIF(C12:G12,">0")&" de "&COUNT(C12:G12) -> 5 de 5 | M12: =IF(ABS(H12)>K12,"Sí","No: dentro de la dispersión") -> Sí
A13: SSP5-8.5 (altas) | B13: Largo 2081-2100 | C13: 6.1423 | D13: 4.1646 | E13: 4.6992 | F13: 3.8475 | G13: 4.018 | H13: =AVERAGE(C13:G13) -> 4.57432 | I13: =MIN(C13:G13) -> 3.8475 | J13: =MAX(C13:G13) -> 6.1423 | K13: =STDEV(C13:G13) -> 0.93270923 | L13: =COUNTIF(C13:G13,">0")&" de "&COUNT(C13:G13) -> 5 de 5 | M13: =IF(ABS(H13)>K13,"Sí","No: dentro de la dispersión") -> Sí
A15: Notas
A16: Media ensamble = promedio simple de los 5 modelos. Desv. est. = dispersión entre modelos (n=5).
A17: '¿Señal > dispersión?' compara el valor absoluto de la media con la desviación entre modelos: si es 'No', el cambio no se distingue del ruido entre modelos.

Sheet Precipitación
A1: Precipitación: cambio respecto a 1995-2014 por modelo (%)
A2: Azul = valor calculado a partir de los NetCDF (entrada). Negro = fórmula. Ventana de plazo menos línea base del mismo modelo.
A4: Escenario | B4: Plazo | C4: ACCESS-CM2 | D4: GFDL-ESM4 | E4: MPI-ESM1-2-LR | F4: MRI-ESM2-0 | G4: NorESM2-MM | H4: Media ensamble | I4: Mínimo | J4: Máximo | K4: Desv. est. | L4: Modelos con aumento | M4: ¿Señal > dispersión?
A5: SSP1-2.6 (bajas) | B5: Corto 2021-2040 | C5: 5.5616 | D5: 0.7978 | E5: -1.1677 | F5: 3.537 | G5: -5.2244 | H5: =AVERAGE(C5:G5) -> 0.70086 | I5: =MIN(C5:G5) -> -5.2244 | J5: =MAX(C5:G5) -> 5.5616 | K5: =STDEV(C5:G5) -> 4.1916615 | L5: =COUNTIF(C5:G5,">0")&" de "&COUNT(C5:G5) -> 3 de 5 | M5: =IF(ABS(H5)>K5,"Sí","No: dentro de la dispersión") -> No: dentro de la dispersión
A6: SSP1-2.6 (bajas) | B6: Mediano 2041-2060 | C6: 13.0702 | D6: -4.3879 | E6: -3.106 | F6: 5.4728 | G6: -1.0109 | H6: =AVERAGE(C6:G6) -> 2.00764 | I6: =MIN(C6:G6) -> -4.3879 | J6: =MAX(C6:G6) -> 13.0702 | K6: =STDEV(C6:G6) -> 7.2551946 | L6: =COUNTIF(C6:G6,">0")&" de "&COUNT(C6:G6) -> 2 de 5 | M6: =IF(ABS(H6)>K6,"Sí","No: dentro de la dispersión") -> No: dentro de la dispersión
A7: SSP1-2.6 (bajas) | B7: Largo 2081-2100 | C7: 13.3702 | D7: -0.0741 | E7: -1.2907 | F7: 4.5791 | G7: -6.0731 | H7: =AVERAGE(C7:G7) -> 2.10228 | I7: =MIN(C7:G7) -> -6.0731 | J7: =MAX(C7:G7) -> 13.3702 | K7: =STDEV(C7:G7) -> 7.3516399 | L7: =COUNTIF(C7:G7,">0")&" de "&COUNT(C7:G7) -> 2 de 5 | M7: =IF(ABS(H7)>K7,"Sí","No: dentro de la dispersión") -> No: dentro de la dispersión
A8: SSP2-4.5 (medias) | B8: Corto 2021-2040 | C8: 7.4719 | D8: -4.0895 | E8: -1.3211 | F8: 0.0085 | G8: -0.4981 | H8: =AVERAGE(C8:G8) -> 0.31434 | I8: =MIN(C8:G8) -> -4.0895 | J8: =MAX(C8:G8) -> 7.4719 | K8: =STDEV(C8:G8) -> 4.3026949 | L8: =COUNTIF(C8:G8,">0")&" de "&COUNT(C8:G8) -> 2 de 5 | M8: =IF(ABS(H8)>K8,"Sí","No: dentro de la dispersión") -> No: dentro de la dispersión
A9: SSP2-4.5 (medias) | B9: Mediano 2041-2060 | C9: 5.3278 | D9: -1.9563 | E9: -0.4139 | F9: 3.6538 | G9: -6.4623 | H9: =AVERAGE(C9:G9) -> 0.02982 | I9: =MIN(C9:G9) -> -6.4623 | J9: =MAX(C9:G9) -> 5.3278 | K9: =STDEV(C9:G9) -> 4.6768313 | L9: =COUNTIF(C9:G9,">0")&" de "&COUNT(C9:G9) -> 2 de 5 | M9: =IF(ABS(H9)>K9,"Sí","No: dentro de la dispersión") -> No: dentro de la dispersión
A10: SSP2-4.5 (medias) | B10: Largo 2081-2100 | C10: 14.1371 | D10: -3.2511 | E10: -4.993 | F10: 0.6227 | G10: -4.2854 | H10: =AVERAGE(C10:G10) -> 0.44606 | I10: =MIN(C10:G10) -> -4.993 | J10: =MAX(C10:G10) -> 14.1371 | K10: =STDEV(C10:G10) -> 7.9547919 | L10: =COUNTIF(C10:G10,">0")&" de "&COUNT(C10:G10) -> 2 de 5 | M10: =IF(ABS(H10)>K10,"Sí","No: dentro de la dispersión") -> No: dentro de la dispersión
A11: SSP5-8.5 (altas) | B11: Corto 2021-2040 | C11: 6.3525 | D11: -5.4042 | E11: -4.7489 | F11: 0.0748 | G11: -3.204 | H11: =AVERAGE(C11:G11) -> -1.38596 | I11: =MIN(C11:G11) -> -5.4042 | J11: =MAX(C11:G11) -> 6.3525 | K11: =STDEV(C11:G11) -> 4.8160791 | L11: =COUNTIF(C11:G11,">0")&" de "&COUNT(C11:G11) -> 2 de 5 | M11: =IF(ABS(H11)>K11,"Sí","No: dentro de la dispersión") -> No: dentro de la dispersión
A12: SSP5-8.5 (altas) | B12: Mediano 2041-2060 | C12: -1.9427 | D12: -7.3865 | E12: -9.1552 | F12: 0.725 | G12: -2.3779 | H12: =AVERAGE(C12:G12) -> -4.02746 | I12: =MIN(C12:G12) -> -9.1552 | J12: =MAX(C12:G12) -> 0.725 | K12: =STDEV(C12:G12) -> 4.0996956 | L12: =COUNTIF(C12:G12,">0")&" de "&COUNT(C12:G12) -> 1 de 5 | M12: =IF(ABS(H12)>K12,"Sí","No: dentro de la dispersión") -> No: dentro de la dispersión
A13: SSP5-8.5 (altas) | B13: Largo 2081-2100 | C13: -5.5619 | D13: -18.202 | E13: -13.9745 | F13: 3.6265 | G13: -4.2306 | H13: =AVERAGE(C13:G13) -> -7.6685 | I13: =MIN(C13:G13) -> -18.202 | J13: =MAX(C13:G13) -> 3.6265 | K13: =STDEV(C13:G13) -> 8.5812907 | L13: =COUNTIF(C13:G13,">0")&" de "&COUNT(C13:G13) -> 1 de 5 | M13: =IF(ABS(H13)>K13,"Sí","No: dentro de la dispersión") -> No: dentro de la dispersión
A15: Notas
A16: Media ensamble = promedio simple de los 5 modelos. Desv. est. = dispersión entre modelos (n=5).
A17: '¿Señal > dispersión?' compara el valor absoluto de la media con la desviación entre modelos: si es 'No', el cambio no se distingue del ruido entre modelos.
A18: Cambio relativo en % respecto a la precipitación media 1995-2014 del mismo modelo (los modelos no reproducen bien la precipitación absoluta local).

Sheet Serie temperatura
A1: Serie temperatura: anomalía anual suavizada (media móvil 10 años), respecto a 1995-2014
A2: Columnas azules = valor por modelo (entrada, calculado de los NetCDF). Media/Mín/Máx = fórmulas. Historical 1950-2014, SSP 2015-2100.
A27: Año | B27: Historical · ACCESS-CM2 | C27: Historical · GFDL-ESM4 | D27: Historical · MPI-ESM1-2-LR | E27: Historical · MRI-ESM2-0 | F27: Historical · NorESM2-MM | G27: SSP1-2.6 (bajas) · ACCESS-CM2 | H27: SSP1-2.6 (bajas) · GFDL-ESM4 | I27: SSP1-2.6 (bajas) · MPI-ESM1-2-LR | J27: SSP1-2.6 (bajas) · MRI-ESM2-0 | K27: SSP1-2.6 (bajas) · NorESM2-MM | L27: SSP2-4.5 (medias) · ACCESS-CM2 | M27: SSP2-4.5 (medias) · GFDL-ESM4 | N27: SSP2-4.5 (medias) · MPI-ESM1-2-LR | O27: SSP2-4.5 (medias) · MRI-ESM2-0 | P27: SSP2-4.5 (medias) · NorESM2-MM | Q27: SSP5-8.5 (altas) · ACCESS-CM2 | R27: SSP5-8.5 (altas) · GFDL-ESM4 | S27: SSP5-8.5 (altas) · MPI-ESM1-2-LR | T27: SSP5-8.5 (altas) · MRI-ESM2-0 | U27: SSP5-8.5 (altas) · NorESM2-MM | V27: Historical · Media | W27: Historical · Mín | X27: Historical · Máx | Y27: SSP1-2.6 (bajas) · Media | Z27: SSP1-2.6 (bajas) · Mín | AA27: SSP1-2.6 (bajas) · Máx | AB27: SSP2-4.5 (medias) · Media | AC27: SSP2-4.5 (medias) · Mín | AD27: SSP2-4.5 (medias) · Máx | AE27: SSP5-8.5 (altas) · Media | AF27: SSP5-8.5 (altas) · Mín | AG27: SSP5-8.5 (altas) · Máx
A28: 1950 | B28: -0.4715 | C28: -0.7786 | D28: -0.3955 | E28: -0.4782 | F28: -0.1548 | V28: =AVERAGE(B28:F28) -> -0.45572 | W28: =MIN(B28:F28) -> -0.7786 | X28: =MAX(B28:F28) -> -0.1548
A29: 1951 | B29: -0.4871 | C29: -0.7454 | D29: -0.5166 | E29: -0.369 | F29: -0.1707 | V29: =AVERAGE(B29:F29) -> -0.45776 | W29: =MIN(B29:F29) -> -0.7454 | X29: =MAX(B29:F29) -> -0.1707
A30: 1952 | B30: -0.5693 | C30: -0.7452 | D30: -0.63 | E30: -0.3989 | F30: -0.2172 | V30: =AVERAGE(B30:F30) -> -0.51212 | W30: =MIN(B30:F30) -> -0.7452 | X30: =MAX(B30:F30) -> -0.2172
A31: 1953 | B31: -0.5614 | C31: -0.7572 | D31: -0.6941 | E31: -0.4432 | F31: -0.2827 | V31: =AVERAGE(B31:F31) -> -0.54772 | W31: =MIN(B31:F31) -> -0.7572 | X31: =MAX(B31:F31) -> -0.2827
A32: 1954 | B32: -0.5501 | C32: -0.7249 | D32: -0.6707 | E32: -0.4232 | F32: -0.3656 | V32: =AVERAGE(B32:F32) -> -0.5469 | W32: =MIN(B32:F32) -> -0.7249 | X32: =MAX(B32:F32) -> -0.3656
A33: 1955 | B33: -0.6159 | C33: -0.6519 | D33: -0.6551 | E33: -0.3886 | F33: -0.3409 | V33: =AVERAGE(B33:F33) -> -0.53048 | W33: =MIN(B33:F33) -> -0.6551 | X33: =MAX(B33:F33) -> -0.3409
A34: 1956 | B34: -0.5928 | C34: -0.6803 | D34: -0.5885 | E34: -0.3946 | F34: -0.3169 | V34: =AVERAGE(B34:F34) -> -0.51462 | W34: =MIN(B34:F34) -> -0.6803 | X34: =MAX(B34:F34) -> -0.3169
A35: 1957 | B35: -0.6233 | C35: -0.6381 | D35: -0.7104 | E35: -0.4638 | F35: -0.2798 | V35: =AVERAGE(B35:F35) -> -0.54308 | W35: =MIN(B35:F35) -> -0.7104 | X35: =MAX(B35:F35) -> -0.2798
A36: 1958 | B36: -0.6085 | C36: -0.6103 | D36: -0.7707 | E36: -0.4729 | F36: -0.2312 | V36: =AVERAGE(B36:F36) -> -0.53872 | W36: =MIN(B36:F36) -> -0.7707 | X36: =MAX(B36:F36) -> -0.2312
A37: 1959 | B37: -0.6715 | C37: -0.6966 | D37: -0.8665 | E37: -0.4235 | F37: -0.231 | V37: =AVERAGE(B37:F37) -> -0.57782 | W37: =MIN(B37:F37) -> -0.8665 | X37: =MAX(B37:F37) -> -0.231
A38: 1960 | B38: -0.7165 | C38: -0.8057 | D38: -0.8903 | E38: -0.4096 | F38: -0.2804 | V38: =AVERAGE(B38:F38) -> -0.6205 | W38: =MIN(B38:F38) -> -0.8903 | X38: =MAX(B38:F38) -> -0.2804
A39: 1961 | B39: -0.7884 | C39: -0.8801 | D39: -0.8147 | E39: -0.5344 | F39: -0.2934 | V39: =AVERAGE(B39:F39) -> -0.6622 | W39: =MIN(B39:F39) -> -0.8801 | X39: =MAX(B39:F39) -> -0.2934
... A92: 2014 | B92: 0.2253 | C92: 0.1812 | D92: 0.1883 | E92: 0.0625 | F92: 0.0986 | V92: =AVERAGE(B92:F92) -> 0.15118 | W92: =MIN(B92:F92) -> 0.0625 | X92: =MAX(B92:F92) -> 0.2253
A93: 2015 | G93: 0.5189 | H93: 0.0167 | I93: 0.3737 | J93: 0.3181 | K93: 0.6349 | L93: 0.5478 | M93: 0.4447 | N93: 0.2527 | O93: 0.1676 | P93: 0.7872 | Q93: 0.6847 | R93: 0.0983 | S93: 0.8224 | T93: 0.3808 | U93: 0.6277 | Y93: =AVERAGE(G93:K93) -> 0.37246 | Z93: =MIN(G93:K93) -> 0.0167 | AA93: =MAX(G93:K93) -> 0.6349 | AB93: =AVERAGE(L93:P93) -> 0.44 | AC93: =MIN(L93:P93) -> 0.1676 | AD93: =MAX(L93:P93) -> 0.7872 | AE93: =AVERAGE(Q93:U93) -> 0.52278 | AF93: =MIN(Q93:U93) -> 0.0983 | AG93: =MAX(Q93:U93) -> 0.8224
A94: 2016 | G94: 0.4829 | H94: 0.1262 | I94: 0.586 | J94: 0.3746 | K94: 0.6452 | L94: 0.5206 | M94: 0.3178 | N94: 0.4226 | O94: 0.1701 | P94: 0.8693 | Q94: 0.7357 | R94: 0.0141 | S94: 0.6249 | T94: 0.3374 | U94: 0.6603 | Y94: =AVERAGE(G94:K94) -> 0.44298 | Z94: =MIN(G94:K94) -> 0.1262 | AA94: =MAX(G94:K94) -> 0.6452 | AB94: =AVERAGE(L94:P94) -> 0.46008 | AC94: =MIN(L94:P94) -> 0.1701 | AD94: =MAX(L94:P94) -> 0.8693 | AE94: =AVERAGE(Q94:U94) -> 0.47448 | AF94: =MIN(Q94:U94) -> 0.0141 | AG94: =MAX(Q94:U94) -> 0.7357
A95: 2017 | G95: 0.4872 | H95: 0.2499 | I95: 0.5914 | J95: 0.3438 | K95: 0.6291 | L95: 0.5241 | M95: 0.2644 | N95: 0.5539 | O95: 0.1786 | P95: 0.8469 | Q95: 0.7871 | R95: 0.0209 | S95: 0.6066 | T95: 0.3304 | U95: 0.6508 | Y95: =AVERAGE(G95:K95) -> 0.46028 | Z95: =MIN(G95:K95) -> 0.2499 | AA95: =MAX(G95:K95) -> 0.6291 | AB95: =AVERAGE(L95:P95) -> 0.47358 | AC95: =MIN(L95:P95) -> 0.1786 | AD95: =MAX(L95:P95) -> 0.8469 | AE95: =AVERAGE(Q95:U95) -> 0.47916 | AF95: =MIN(Q95:U95) -> 0.0209 | AG95: =MAX(Q95:U95) -> 0.7871
A96: 2018 | G96: 0.5573 | H96: 0.2595 | I96: 0.5861 | J96: 0.2835 | K96: 0.5988 | L96: 0.5833 | M96: 0.2569 | N96: 0.5687 | O96: 0.2806 | P96: 0.8179 | Q96: 0.695 | R96: 0.0463 | S96: 0.623 | T96: 0.3207 | U96: 0.6454 | Y96: =AVERAGE(G96:K96) -> 0.45704 | Z96: =MIN(G96:K96) -> 0.2595 | AA96: =MAX(G96:K96) -> 0.5988 | AB96: =AVERAGE(L96:P96) -> 0.50148 | AC96: =MIN(L96:P96) -> 0.2569 | AD96: =MAX(L96:P96) -> 0.8179 | AE96: =AVERAGE(Q96:U96) -> 0.46608 | AF96: =MIN(Q96:U96) -> 0.0463 | AG96: =MAX(Q96:U96) -> 0.695
A97: 2019 | G97: 0.5878 | H97: 0.1982 | I97: 0.5075 | J97: 0.309 | K97: 0.5674 | L97: 0.5755 | M97: 0.3044 | N97: 0.5318 | O97: 0.3493 | P97: 0.7822 | Q97: 0.7499 | R97: 0.0225 | S97: 0.7418 | T97: 0.3512 | U97: 0.6061 | Y97: =AVERAGE(G97:K97) -> 0.43398 | Z97: =MIN(G97:K97) -> 0.1982 | AA97: =MAX(G97:K97) -> 0.5878 | AB97: =AVERAGE(L97:P97) -> 0.50864 | AC97: =MIN(L97:P97) -> 0.3044 | AD97: =MAX(L97:P97) -> 0.7822 | AE97: =AVERAGE(Q97:U97) -> 0.4943 | AF97: =MIN(Q97:U97) -> 0.0225 | AG97: =MAX(Q97:U97) -> 0.7499
A98: 2020 | G98: 0.7002 | H98: 0.1727 | I98: 0.426 | J98: 0.4025 | K98: 0.5848 | L98: 0.6041 | M98: 0.3279 | N98: 0.5454 | O98: 0.346 | P98: 0.7207 | Q98: 0.7196 | R98: 0.0538 | S98: 0.77 | T98: 0.4109 | U98: 0.6554 | Y98: =AVERAGE(G98:K98) -> 0.45724 | Z98: =MIN(G98:K98) -> 0.1727 | AA98: =MAX(G98:K98) -> 0.7002 | AB98: =AVERAGE(L98:P98) -> 0.50882 | AC98: =MIN(L98:P98) -> 0.3279 | AD98: =MAX(L98:P98) -> 0.7207 | AE98: =AVERAGE(Q98:U98) -> 0.52194 | AF98: =MIN(Q98:U98) -> 0.0538 | AG98: =MAX(Q98:U98) -> 0.77
A99: 2021 | G99: 0.7529 | H99: 0.2487 | I99: 0.5194 | J99: 0.4335 | K99: 0.6106 | L99: 0.6157 | M99: 0.4043 | N99: 0.593 | O99: 0.3553 | P99: 0.5848 | Q99: 0.7495 | R99: 0.1563 | S99: 0.9197 | T99: 0.5051 | U99: 0.7273 | Y99: =AVERAGE(G99:K99) -> 0.51302 | Z99: =MIN(G99:K99) -> 0.2487 | AA99: =MAX(G99:K99) -> 0.7529 | AB99: =AVERAGE(L99:P99) -> 0.51062 | AC99: =MIN(L99:P99) -> 0.3553 | AD99: =MAX(L99:P99) -> 0.6157 | AE99: =AVERAGE(Q99:U99) -> 0.61158 | AF99: =MIN(Q99:U99) -> 0.1563 | AG99: =MAX(Q99:U99) -> 0.9197
A100: 2022 | G100: 0.7349 | H100: 0.31 | I100: 0.5732 | J100: 0.4551 | K100: 0.6608 | L100: 0.6481 | M100: 0.4544 | N100: 0.5044 | O100: 0.4203 | P100: 0.5459 | Q100: 0.76 | R100: 0.2225 | S100: 0.8612 | T100: 0.5169 | U100: 0.697 | Y100: =AVERAGE(G100:K100) -> 0.5468 | Z100: =MIN(G100:K100) -> 0.31 | AA100: =MAX(G100:K100) -> 0.7349 | AB100: =AVERAGE(L100:P100) -> 0.51462 | AC100: =MIN(L100:P100) -> 0.4203 | AD100: =MAX(L100:P100) -> 0.6481 | AE100: =AVERAGE(Q100:U100) -> 0.61152 | AF100: =MIN(Q100:U100) -> 0.2225 | AG100: =MAX(Q100:U100) -> 0.8612
A101: 2023 | G101: 0.8095 | H101: 0.2511 | I101: 0.5968 | J101: 0.4763 | K101: 0.7138 | L101: 0.6883 | M101: 0.4721 | N101: 0.492 | O101: 0.4686 | P101: 0.5089 | Q101: 0.8793 | R101: 0.2549 | S101: 0.9203 | T101: 0.5831 | U101: 0.6362 | Y101: =AVERAGE(G101:K101) -> 0.5695 | Z101: =MIN(G101:K101) -> 0.2511 | AA101: =MAX(G101:K101) -> 0.8095 | AB101: =AVERAGE(L101:P101) -> 0.52598 | AC101: =MIN(L101:P101) -> 0.4686 | AD101: =MAX(L101:P101) -> 0.6883 | AE101: =AVERAGE(Q101:U101) -> 0.65476 | AF101: =MIN(Q101:U101) -> 0.2549 | AG101: =MAX(Q101:U101) -> 0.9203
A102: 2024 | G102: 0.9305 | H102: 0.2925 | I102: 0.6095 | J102: 0.5504 | K102: 0.7894 | L102: 0.711 | M102: 0.4316 | N102: 0.4819 | O102: 0.5782 | P102: 0.5217 | Q102: 0.9378 | R102: 0.34 | S102: 0.9355 | T102: 0.5721 | U102: 0.6182 | Y102: =AVERAGE(G102:K102) -> 0.63446 | Z102: =MIN(G102:K102) -> 0.2925 | AA102: =MAX(G102:K102) -> 0.9305 | AB102: =AVERAGE(L102:P102) -> 0.54488 | AC102: =MIN(L102:P102) -> 0.4316 | AD102: =MAX(L102:P102) -> 0.711 | AE102: =AVERAGE(Q102:U102) -> 0.68072 | AF102: =MIN(Q102:U102) -> 0.34 | AG102: =MAX(Q102:U102) -> 0.9378
A103: 2025 | G103: 1.0028 | H103: 0.3949 | I103: 0.5576 | J103: 0.5626 | K103: 0.8223 | L103: 0.7594 | M103: 0.3699 | N103: 0.6504 | O103: 0.7229 | P103: 0.5271 | Q103: 0.887 | R103: 0.4189 | S103: 0.9074 | T103: 0.5847 | U103: 0.61 | Y103: =AVERAGE(G103:K103) -> 0.66804 | Z103: =MIN(G103:K103) -> 0.3949 | AA103: =MAX(G103:K103) -> 1.0028 | AB103: =AVERAGE(L103:P103) -> 0.60594 | AC103: =MIN(L103:P103) -> 0.3699 | AD103: =MAX(L103:P103) -> 0.7594 | AE103: =AVERAGE(Q103:U103) -> 0.6816 | AF103: =MIN(Q103:U103) -> 0.4189 | AG103: =MAX(Q103:U103) -> 0.9074
A104: 2026 | G104: 1.1173 | H104: 0.3949 | I104: 0.5092 | J104: 0.5524 | K104: 0.8118 | L104: 0.7975 | M104: 0.4926 | N104: 0.6739 | O104: 0.7358 | P104: 0.5329 | Q104: 0.8985 | R104: 0.4801 | S104: 1.0589 | T104: 0.6379 | U104: 0.6052 | Y104: =AVERAGE(G104:K104) -> 0.67712 | Z104: =MIN(G104:K104) -> 0.3949 | AA104: =MAX(G104:K104) -> 1.1173 | AB104: =AVERAGE(L104:P104) -> 0.64654 | AC104: =MIN(L104:P104) -> 0.4926 | AD104: =MAX(L104:P104) -> 0.7975 | AE104: =AVERAGE(Q104:U104) -> 0.73612 | AF104: =MIN(Q104:U104) -> 0.4801 | AG104: =MAX(Q104:U104) -> 1.0589
... A178: 2100 | G178: 1.7552 | H178: 0.687 | I178: 0.4958 | J178: 1.0561 | K178: 1.1174 | L178: 3.3929 | M178: 1.6551 | N178: 1.855 | O178: 1.7933 | P178: 1.9653 | Q178: 6.8935 | R178: 4.4756 | S178: 5.2282 | T178: 4.0889 | U178: 4.3153 | Y178: =AVERAGE(G178:K178) -> 1.0223 | Z178: =MIN(G178:K178) -> 0.4958 | AA178: =MAX(G178:K178) -> 1.7552 | AB178: =AVERAGE(L178:P178) -> 2.13232 | AC178: =MIN(L178:P178) -> 1.6551 | AD178: =MAX(L178:P178) -> 3.3929 | AE178: =AVERAGE(Q178:U178) -> 5.0003 | AF178: =MIN(Q178:U178) -> 4.0889 | AG178: =MAX(Q178:U178) -> 6.8935

Sheet Serie precipitación
A1: Serie precipitación: anomalía anual suavizada (media móvil 10 años), respecto a 1995-2014
A2: Columnas azules = valor por modelo (entrada, calculado de los NetCDF). Media/Mín/Máx = fórmulas. Historical 1950-2014, SSP 2015-2100.
A27: Año | B27: Historical · ACCESS-CM2 | C27: Historical · GFDL-ESM4 | D27: Historical · MPI-ESM1-2-LR | E27: Historical · MRI-ESM2-0 | F27: Historical · NorESM2-MM | G27: SSP1-2.6 (bajas) · ACCESS-CM2 | H27: SSP1-2.6 (bajas) · GFDL-ESM4 | I27: SSP1-2.6 (bajas) · MPI-ESM1-2-LR | J27: SSP1-2.6 (bajas) · MRI-ESM2-0 | K27: SSP1-2.6 (bajas) · NorESM2-MM | L27: SSP2-4.5 (medias) · ACCESS-CM2 | M27: SSP2-4.5 (medias) · GFDL-ESM4 | N27: SSP2-4.5 (medias) · MPI-ESM1-2-LR | O27: SSP2-4.5 (medias) · MRI-ESM2-0 | P27: SSP2-4.5 (medias) · NorESM2-MM | Q27: SSP5-8.5 (altas) · ACCESS-CM2 | R27: SSP5-8.5 (altas) · GFDL-ESM4 | S27: SSP5-8.5 (altas) · MPI-ESM1-2-LR | T27: SSP5-8.5 (altas) · MRI-ESM2-0 | U27: SSP5-8.5 (altas) · NorESM2-MM | V27: Historical · Media | W27: Historical · Mín | X27: Historical · Máx | Y27: SSP1-2.6 (bajas) · Media | Z27: SSP1-2.6 (bajas) · Mín | AA27: SSP1-2.6 (bajas) · Máx | AB27: SSP2-4.5 (medias) · Media | AC27: SSP2-4.5 (medias) · Mín | AD27: SSP2-4.5 (medias) · Máx | AE27: SSP5-8.5 (altas) · Media | AF27: SSP5-8.5 (altas) · Mín | AG27: SSP5-8.5 (altas) · Máx
A28: 1950 | B28: 5.4623 | C28: 9.8891 | D28: -3.6206 | E28: -1.6102 | F28: 1.6682 | V28: =AVERAGE(B28:F28) -> 2.35776 | W28: =MIN(B28:F28) -> -3.6206 | X28: =MAX(B28:F28) -> 9.8891
A29: 1951 | B29: 6.0133 | C29: 8.6111 | D29: -1.8494 | E29: -3.181 | F29: 2.0842 | V29: =AVERAGE(B29:F29) -> 2.33564 | W29: =MIN(B29:F29) -> -3.181 | X29: =MAX(B29:F29) -> 8.6111
A30: 1952 | B30: 6.501 | C30: 7.3621 | D30: -1.6959 | E30: -3.6611 | F30: 3.5464 | V30: =AVERAGE(B30:F30) -> 2.4105 | W30: =MIN(B30:F30) -> -3.6611 | X30: =MAX(B30:F30) -> 7.3621
A31: 1953 | B31: 4.6983 | C31: 5.4399 | D31: -2.167 | E31: -6.1953 | F31: 3.0782 | V31: =AVERAGE(B31:F31) -> 0.97082 | W31: =MIN(B31:F31) -> -6.1953 | X31: =MAX(B31:F31) -> 5.4399
A32: 1954 | B32: 3.6823 | C32: 3.4777 | D32: -4.3944 | E32: -7.7273 | F32: 3.0298 | V32: =AVERAGE(B32:F32) -> -0.38638 | W32: =MIN(B32:F32) -> -7.7273 | X32: =MAX(B32:F32) -> 3.6823
A33: 1955 | B33: 3.5504 | C33: 6.0909 | D33: -2.6355 | E33: -7.515 | F33: 3.5099 | V33: =AVERAGE(B33:F33) -> 0.60014 | W33: =MIN(B33:F33) -> -7.515 | X33: =MAX(B33:F33) -> 6.0909
A34: 1956 | B34: 3.1413 | C34: 4.9788 | D34: -3.2322 | E34: -6.8207 | F34: 1.9982 | V34: =AVERAGE(B34:F34) -> 0.01308 | W34: =MIN(B34:F34) -> -6.8207 | X34: =MAX(B34:F34) -> 4.9788
A35: 1957 | B35: 2.7658 | C35: 1.3521 | D35: 0.1784 | E35: -7.7629 | F35: 2.8263 | V35: =AVERAGE(B35:F35) -> -0.12806 | W35: =MIN(B35:F35) -> -7.7629 | X35: =MAX(B35:F35) -> 2.8263
A36: 1958 | B36: 3.137 | C36: 2.6778 | D36: 1.3385 | E36: -7.274 | F36: 3.4894 | V36: =AVERAGE(B36:F36) -> 0.67374 | W36: =MIN(B36:F36) -> -7.274 | X36: =MAX(B36:F36) -> 3.4894
A37: 1959 | B37: 3.9101 | C37: 3.9773 | D37: 1.2248 | E37: -7.0686 | F37: 3.1301 | V37: =AVERAGE(B37:F37) -> 1.03474 | W37: =MIN(B37:F37) -> -7.0686 | X37: =MAX(B37:F37) -> 3.9773
A38: 1960 | B38: 4.8856 | C38: 6.312 | D38: -0.2382 | E38: -6.3056 | F38: 3.0457 | V38: =AVERAGE(B38:F38) -> 1.5399 | W38: =MIN(B38:F38) -> -6.3056 | X38: =MAX(B38:F38) -> 6.312
A39: 1961 | B39: 4.6552 | C39: 6.0592 | D39: -2.2611 | E39: -3.747 | F39: 1.2529 | V39: =AVERAGE(B39:F39) -> 1.19184 | W39: =MIN(B39:F39) -> -3.747 | X39: =MAX(B39:F39) -> 6.0592
... A92: 2014 | B92: -0.3502 | C92: 3.9574 | D92: -1.4054 | E92: -0.6024 | F92: -0.6269 | V92: =AVERAGE(B92:F92) -> 0.1945 | W92: =MIN(B92:F92) -> -1.4054 | X92: =MAX(B92:F92) -> 3.9574
A93: 2015 | G93: 8.8589 | H93: -2.2455 | I93: -2.4825 | J93: -0.1406 | K93: -9.0688 | L93: 6.7971 | M93: -0.9468 | N93: -3.4139 | O93: -1.183 | P93: -6.0683 | Q93: -0.3751 | R93: 4.9087 | S93: -11.2531 | T93: -3.9156 | U93: -8.3149 | Y93: =AVERAGE(G93:K93) -> -1.0157 | Z93: =MIN(G93:K93) -> -9.0688 | AA93: =MAX(G93:K93) -> 8.8589 | AB93: =AVERAGE(L93:P93) -> -0.96298 | AC93: =MIN(L93:P93) -> -6.0683 | AD93: =MAX(L93:P93) -> 6.7971 | AE93: =AVERAGE(Q93:U93) -> -3.79 | AF93: =MIN(Q93:U93) -> -11.2531 | AG93: =MAX(Q93:U93) -> 4.9087
A94: 2016 | G94: 8.4716 | H94: -4.7281 | I94: -6.332 | J94: 2.9331 | K94: -9.586 | L94: 7.471 | M94: 1.22 | N94: -7.2098 | O94: -3.2228 | P94: -7.632 | Q94: -0.8513 | R94: 5.0942 | S94: -10.0807 | T94: -3.0141 | U94: -8.2565 | Y94: =AVERAGE(G94:K94) -> -1.84828 | Z94: =MIN(G94:K94) -> -9.586 | AA94: =MAX(G94:K94) -> 8.4716 | AB94: =AVERAGE(L94:P94) -> -1.87472 | AC94: =MIN(L94:P94) -> -7.632 | AD94: =MAX(L94:P94) -> 7.471 | AE94: =AVERAGE(Q94:U94) -> -3.42168 | AF94: =MIN(Q94:U94) -> -10.0807 | AG94: =MAX(Q94:U94) -> 5.0942
A95: 2017 | G95: 7.5163 | H95: -2.9217 | I95: -3.1172 | J95: 3.2509 | K95: -8.3118 | L95: 5.7258 | M95: 1.1352 | N95: -7.3065 | O95: -1.147 | P95: -6.1659 | Q95: 3.9064 | R95: 6.6831 | S95: -10.394 | T95: -0.9501 | U95: -8.8346 | Y95: =AVERAGE(G95:K95) -> -0.7167 | Z95: =MIN(G95:K95) -> -8.3118 | AA95: =MAX(G95:K95) -> 7.5163 | AB95: =AVERAGE(L95:P95) -> -1.55168 | AC95: =MIN(L95:P95) -> -7.3065 | AD95: =MAX(L95:P95) -> 5.7258 | AE95: =AVERAGE(Q95:U95) -> -1.91784 | AF95: =MIN(Q95:U95) -> -10.394 | AG95: =MAX(Q95:U95) -> 6.6831
A96: 2018 | G96: 5.0123 | H96: -2.0292 | I96: -2.2975 | J96: 3.2612 | K96: -8.5018 | L96: 5.5722 | M96: -0.6523 | N96: -6.7857 | O96: -1.8916 | P96: -3.9149 | Q96: 3.8498 | R96: 5.3822 | S96: -9.6642 | T96: 1.1809 | U96: -10.2836 | Y96: =AVERAGE(G96:K96) -> -0.911 | Z96: =MIN(G96:K96) -> -8.5018 | AA96: =MAX(G96:K96) -> 5.0123 | AB96: =AVERAGE(L96:P96) -> -1.53446 | AC96: =MIN(L96:P96) -> -6.7857 | AD96: =MAX(L96:P96) -> 5.5722 | AE96: =AVERAGE(Q96:U96) -> -1.90698 | AF96: =MIN(Q96:U96) -> -10.2836 | AG96: =MAX(Q96:U96) -> 5.3822
A97: 2019 | G97: 4.0087 | H97: 2.0808 | I97: -1.5928 | J97: 1.2955 | K97: -7.5945 | L97: 4.7807 | M97: -2.4988 | N97: -6.0634 | O97: -1.06 | P97: -5.8005 | Q97: 5.9503 | R97: 3.3148 | S97: -10.8325 | T97: -0.6722 | U97: -8.7062 | Y97: =AVERAGE(G97:K97) -> -0.36046 | Z97: =MIN(G97:K97) -> -7.5945 | AA97: =MAX(G97:K97) -> 4.0087 | AB97: =AVERAGE(L97:P97) -> -2.1284 | AC97: =MIN(L97:P97) -> -6.0634 | AD97: =MAX(L97:P97) -> 4.7807 | AE97: =AVERAGE(Q97:U97) -> -2.18916 | AF97: =MIN(Q97:U97) -> -10.8325 | AG97: =MAX(Q97:U97) -> 5.9503
A98: 2020 | G98: 2.4807 | H98: 1.7633 | I98: -1.7475 | J98: 0.8849 | K98: -7.1247 | L98: 4.8891 | M98: -3.0917 | N98: -4.5542 | O98: -0.4066 | P98: -5.3419 | Q98: 4.8551 | R98: 3.3451 | S98: -10.6414 | T98: -2.0809 | U98: -9.1504 | Y98: =AVERAGE(G98:K98) -> -0.74866 | Z98: =MIN(G98:K98) -> -7.1247 | AA98: =MAX(G98:K98) -> 2.4807 | AB98: =AVERAGE(L98:P98) -> -1.70106 | AC98: =MIN(L98:P98) -> -5.3419 | AD98: =MAX(L98:P98) -> 4.8891 | AE98: =AVERAGE(Q98:U98) -> -2.7345 | AF98: =MIN(Q98:U98) -> -10.6414 | AG98: =MAX(Q98:U98) -> 4.8551
A99: 2021 | G99: 4.8508 | H99: 0.1558 | I99: -3.2442 | J99: 1.3502 | K99: -7.8417 | L99: 5.5483 | M99: -3.003 | N99: -4.9947 | O99: -0.9274 | P99: -4.6945 | Q99: 5.7146 | R99: 1.2712 | S99: -12.1764 | T99: 0.2694 | U99: -11.1801 | Y99: =AVERAGE(G99:K99) -> -0.94582 | Z99: =MIN(G99:K99) -> -7.8417 | AA99: =MAX(G99:K99) -> 4.8508 | AB99: =AVERAGE(L99:P99) -> -1.61426 | AC99: =MIN(L99:P99) -> -4.9947 | AD99: =MAX(L99:P99) -> 5.5483 | AE99: =AVERAGE(Q99:U99) -> -3.22026 | AF99: =MIN(Q99:U99) -> -12.1764 | AG99: =MAX(Q99:U99) -> 5.7146
A100: 2022 | G100: 5.0706 | H100: 0.2035 | I100: -3.6776 | J100: 0.0677 | K100: -5.4411 | L100: 4.787 | M100: -0.9794 | N100: -4.9429 | O100: -1.5952 | P100: -3.1604 | Q100: 5.6059 | R100: 0.2997 | S100: -9.7811 | T100: 1.1217 | U100: -9.0294 | Y100: =AVERAGE(G100:K100) -> -0.75538 | Z100: =MIN(G100:K100) -> -5.4411 | AA100: =MAX(G100:K100) -> 5.0706 | AB100: =AVERAGE(L100:P100) -> -1.17818 | AC100: =MIN(L100:P100) -> -4.9429 | AD100: =MAX(L100:P100) -> 4.787 | AE100: =AVERAGE(Q100:U100) -> -2.35664 | AF100: =MIN(Q100:U100) -> -9.7811 | AG100: =MAX(Q100:U100) -> 5.6059
A101: 2023 | G101: 4.4217 | H101: -0.4761 | I101: -4.1604 | J101: 0.8546 | K101: -4.6651 | L101: 6.5572 | M101: -3.1336 | N101: -5.3828 | O101: -3.1425 | P101: -1.8058 | Q101: 5.4434 | R101: -0.3227 | S101: -10.1777 | T101: 1.2044 | U101: -7.4456 | Y101: =AVERAGE(G101:K101) -> -0.80506 | Z101: =MIN(G101:K101) -> -4.6651 | AA101: =MAX(G101:K101) -> 4.4217 | AB101: =AVERAGE(L101:P101) -> -1.3815 | AC101: =MIN(L101:P101) -> -5.3828 | AD101: =MAX(L101:P101) -> 6.5572 | AE101: =AVERAGE(Q101:U101) -> -2.25964 | AF101: =MIN(Q101:U101) -> -10.1777 | AG101: =MAX(Q101:U101) -> 5.4434
A102: 2024 | G102: 5.446 | H102: 0.8433 | I102: -2.3166 | J102: 0.8417 | K102: -5.9121 | L102: 7.0254 | M102: 0.5355 | N102: -4.7745 | O102: -2.8094 | P102: -0.6751 | Q102: 9.4114 | R102: -0.2463 | S102: -8.6048 | T102: 2.2099 | U102: -4.5377 | Y102: =AVERAGE(G102:K102) -> -0.21954 | Z102: =MIN(G102:K102) -> -5.9121 | AA102: =MAX(G102:K102) -> 5.446 | AB102: =AVERAGE(L102:P102) -> -0.13962 | AC102: =MIN(L102:P102) -> -4.7745 | AD102: =MAX(L102:P102) -> 7.0254 | AE102: =AVERAGE(Q102:U102) -> -0.3535 | AF102: =MIN(Q102:U102) -> -8.6048 | AG102: =MAX(Q102:U102) -> 9.4114
A103: 2025 | G103: 4.0124 | H103: 1.722 | I103: -2.6127 | J103: 0.7495 | K103: -5.2042 | L103: 7.4753 | M103: -2.5107 | N103: -5.0349 | O103: -2.8401 | P103: -1.9763 | Q103: 7.4972 | R103: -2.0172 | S103: -8.9018 | T103: 3.2563 | U103: -3.0402 | Y103: =AVERAGE(G103:K103) -> -0.2666 | Z103: =MIN(G103:K103) -> -5.2042 | AA103: =MAX(G103:K103) -> 4.0124 | AB103: =AVERAGE(L103:P103) -> -0.97734 | AC103: =MIN(L103:P103) -> -5.0349 | AD103: =MAX(L103:P103) -> 7.4753 | AE103: =AVERAGE(Q103:U103) -> -0.64114 | AF103: =MIN(Q103:U103) -> -8.9018 | AG103: =MAX(Q103:U103) -> 7.4972
A104: 2026 | G104: 3.8361 | H104: 2.7299 | I104: -0.4144 | J104: 1.7868 | K104: -4.1824 | L104: 6.0044 | M104: -2.7491 | N104: -3.475 | O104: -0.9707 | P104: 0.6703 | Q104: 7.6684 | R104: -3.556 | S104: -9.5222 | T104: 3.0294 | U104: -2.8379 | Y104: =AVERAGE(G104:K104) -> 0.7512 | Z104: =MIN(G104:K104) -> -4.1824 | AA104: =MAX(G104:K104) -> 3.8361 | AB104: =AVERAGE(L104:P104) -> -0.10402 | AC104: =MIN(L104:P104) -> -3.475 | AD104: =MAX(L104:P104) -> 6.0044 | AE104: =AVERAGE(Q104:U104) -> -1.04366 | AF104: =MIN(Q104:U104) -> -9.5222 | AG104: =MAX(Q104:U104) -> 7.6684
... A178: 2100 | G178: 7.8531 | H178: -1.9698 | I178: -2.8026 | J178: 3.9249 | K178: -9.5454 | L178: 12.33 | M178: -6.7742 | N178: -2.2486 | O178: 0.1298 | P178: -1.7899 | Q178: 0.4629 | R178: -14.0561 | S178: -18.4199 | T178: 1.5908 | U178: -6.3448 | Y178: =AVERAGE(G178:K178) -> -0.50796 | Z178: =MIN(G178:K178) -> -9.5454 | AA178: =MAX(G178:K178) -> 7.8531 | AB178: =AVERAGE(L178:P178) -> 0.32942 | AC178: =MIN(L178:P178) -> -6.7742 | AD178: =MAX(L178:P178) -> 12.33 | AE178: =AVERAGE(Q178:U178) -> -7.35342 | AF178: =MIN(Q178:U178) -> -18.4199 | AG178: =MAX(Q178:U178) -> 1.5908

Sheet Ciclo estacional
A1: Ciclo estacional: línea base 1995-2014 y cambio mensual por escenario y plazo (media del ensamble)
A2: Valores calculados en Python (media de los 5 modelos, cada uno contra su propia línea base). El Meta tiene estación lluviosa ~abril-noviembre.
E3: Cambio de temperatura (°C) | O3: Cambio de precipitación (%)
A4: Mes | B4: Temp. base (°C) | C4: Precip. base (mm/día) | E4: Δ°C SSP1-2.6 Corto | F4: Δ°C SSP1-2.6 Mediano | G4: Δ°C SSP1-2.6 Largo | H4: Δ°C SSP2-4.5 Corto | I4: Δ°C SSP2-4.5 Mediano | J4: Δ°C SSP2-4.5 Largo | K4: Δ°C SSP5-8.5 Corto | L4: Δ°C SSP5-8.5 Mediano | M4: Δ°C SSP5-8.5 Largo | O4: Δ% SSP1-2.6 Corto | P4: Δ% SSP1-2.6 Mediano | Q4: Δ% SSP1-2.6 Largo | R4: Δ% SSP2-4.5 Corto | S4: Δ% SSP2-4.5 Mediano | T4: Δ% SSP2-4.5 Largo | U4: Δ% SSP5-8.5 Corto | V4: Δ% SSP5-8.5 Mediano | W4: Δ% SSP5-8.5 Largo
A5: Ene | B5: 23.925 | C5: 0.536 | E5: 0.693 | F5: 1.119 | G5: 1.088 | H5: 0.743 | I5: 1.412 | J5: 2.397 | K5: 0.99 | L5: 2.215 | M5: 5.342 | O5: 12.41 | P5: 6.95 | Q5: 51.63 | R5: 5.7 | S5: 22.22 | T5: 8.8 | U5: -0.12 | V5: 0.71 | W5: -4.28
A6: Feb | B6: 25.235 | C6: 0.989 | E6: 0.893 | F6: 1.211 | G6: 1.167 | H6: 0.824 | I6: 1.624 | J6: 2.39 | K6: 1.155 | L6: 2.246 | M6: 5.401 | O6: -8.8 | P6: 16.88 | Q6: 15.56 | R6: 12.42 | S6: -15.74 | T6: 24.77 | U6: 0.87 | V6: 5.42 | W6: 11.53
A7: Mar | B7: 25.753 | C7: 2.375 | E7: 0.962 | F7: 1.056 | G7: 1.203 | H7: 0.808 | I7: 1.724 | J7: 2.059 | K7: 1.127 | L7: 2.137 | M7: 5.049 | O7: 0.79 | P7: 25.33 | Q7: 12.54 | R7: 19.94 | S7: -1.79 | T7: 42.2 | U7: 11.67 | V7: 20.83 | W7: 20.59
A8: Abr | B8: 24.61 | C8: 6.443 | E8: 0.602 | F8: 1.037 | G8: 1.053 | H8: 0.681 | I8: 1.418 | J8: 2.007 | K8: 0.734 | L8: 1.812 | M8: 4.193 | O8: 10.7 | P8: 6.64 | Q8: 7.74 | R8: 2.81 | S8: -2.03 | T8: 10.67 | U8: 7.53 | V8: -0.32 | W8: 3.8
A9: May | B9: 23.082 | C9: 9.73 | E9: 0.647 | F9: 0.979 | G9: 1.098 | H9: 0.706 | I9: 1.288 | J9: 1.928 | K9: 0.653 | L9: 1.651 | M9: 3.877 | O9: 8.99 | P9: 8.62 | Q9: 5.56 | R9: 2.72 | S9: 3.19 | T9: 9.16 | U9: 3.61 | V9: 3.01 | W9: 4.35
A10: Jun | B10: 22.141 | C10: 9.86 | E10: 0.745 | F10: 1.033 | G10: 1.113 | H10: 0.766 | I10: 1.278 | J10: 2.053 | K10: 0.79 | L10: 1.628 | M10: 3.908 | O10: 3.25 | P10: 3.54 | Q10: 9.1 | R10: -0.5 | S10: 8.69 | T10: 7.85 | U10: 5.6 | V10: 3.81 | W10: 10.36
A11: Jul | B11: 21.98 | C11: 8.815 | E11: 0.644 | F11: 0.988 | G11: 0.91 | H11: 0.677 | I11: 1.218 | J11: 2.003 | K11: 0.75 | L11: 1.631 | M11: 4.001 | O11: -4.41 | P11: -0.05 | Q11: -2.42 | R11: -2.81 | S11: -3.12 | T11: -1.82 | U11: -4.37 | V11: -5.97 | W11: 1.75
A12: Ago | B12: 22.708 | C12: 7.547 | E12: 0.705 | F12: 1.007 | G12: 1.028 | H12: 0.711 | I12: 1.265 | J12: 2.074 | K12: 0.862 | L12: 1.757 | M12: 4.342 | O12: -4.68 | P12: -2.67 | Q12: -4.14 | R12: -4.22 | S12: -3.02 | T12: -10.44 | U12: -6.93 | V12: -6.37 | W12: -20.21
A13: Sep | B13: 23.573 | C13: 7.281 | E13: 0.766 | F13: 1.154 | G13: 1.09 | H13: 0.808 | I13: 1.348 | J13: 2.221 | K13: 0.944 | L13: 1.987 | M13: 4.764 | O13: -9.35 | P13: -12.34 | Q13: -9.79 | R13: -6.51 | S13: -8.94 | T13: -19.19 | U13: -14.75 | V13: -22.22 | W13: -36.76
A14: Oct | B14: 23.725 | C14: 7.99 | E14: 0.717 | F14: 1.079 | G14: 0.979 | H14: 0.725 | I14: 1.33 | J14: 2.171 | K14: 0.865 | L14: 1.852 | M14: 4.761 | O14: -9.12 | P14: -9.48 | Q14: -3.66 | R14: -6.67 | S14: -7.23 | T14: -17.78 | U14: -6.74 | V14: -16.84 | W14: -35.38
A15: Nov | B15: 23.501 | C15: 6.338 | E15: 0.672 | F15: 0.955 | G15: 0.974 | H15: 0.707 | I15: 1.292 | J15: 1.999 | K15: 0.811 | L15: 1.698 | M15: 4.32 | O15: 15.16 | P15: 10.02 | Q15: 4.13 | R15: 5.12 | S15: 2.37 | T15: 2.89 | U15: 0.18 | V15: -2.92 | W15: -13.05
A16: Dic | B16: 23.217 | C16: 1.363 | E16: 0.762 | F16: 1.127 | G16: 1.094 | H16: 0.781 | I16: 1.443 | J16: 2.28 | K16: 1.025 | L16: 2.082 | M16: 4.934 | O16: 42.5 | P16: 40 | Q16: 20.5 | R16: 48.03 | S16: 44.97 | T16: 52.48 | U16: 23.22 | V16: 25.6 | W16: 24.9
A17: Media anual | B17: =AVERAGE(B5:B16) -> 23.620833 | C17: =AVERAGE(C5:C16) -> 5.77225 | E17: =AVERAGE(E5:E16) -> 0.734 | F17: =AVERAGE(F5:F16) -> 1.0620833 | G17: =AVERAGE(G5:G16) -> 1.0664167 | H17: =AVERAGE(H5:H16) -> 0.74475 | I17: =AVERAGE(I5:I16) -> 1.3866667 | J17: =AVERAGE(J5:J16) -> 2.1318333 | K17: =AVERAGE(K5:K16) -> 0.89216667 | L17: =AVERAGE(L5:L16) -> 1.8913333 | M17: =AVERAGE(M5:M16) -> 4.5743333 | O17: =AVERAGE(O5:O16) -> 4.7866667 | P17: =AVERAGE(P5:P16) -> 7.7866667 | Q17: =AVERAGE(Q5:Q16) -> 8.8958333 | R17: =AVERAGE(R5:R16) -> 6.3358333 | S17: =AVERAGE(S5:S16) -> 3.2975 | T17: =AVERAGE(T5:T16) -> 9.1325 | U17: =AVERAGE(U5:U16) -> 1.6475 | V17: =AVERAGE(V5:V16) -> 0.395 | W17: =AVERAGE(W5:W16) -> -2.7
A18: Nota: en los meses secos (dic-feb) la precipitación base es muy baja (~0,5-1 mm/día), por lo que los cambios porcentuales se inflan; en el informe conviene citar también el cambio absoluto.

Sheet Comparación obs
A1: Modelos (Historical 1995-2014) frente a observaciones
A2: ERA5: mismo recuadro que los modelos. CHIRPS: promedio de la región. IDEAM: promedio de estaciones, temperatura media aproximada como (Tmax+Tmin)/2.
A4: Variable | B4: Referencia | C4: Modelo | D4: Media modelo | E4: Media observada | F4: Sesgo (modelo - obs.) | G4: Sesgo (%) | H4: RMSE ciclo anual | I4: Correlación ciclo anual | J4: Unidad
A5: Temperatura | B5: ERA5 | C5: ACCESS-CM2 | D5: 23.190001 | E5: 23.65 | F5: =D5-E5 -> -0.45999947 | H5: 0.86 | I5: 0.711 | J5: °C
A6: Temperatura | B6: ERA5 | C6: GFDL-ESM4 | D6: 23.209999 | E6: 23.65 | F6: =D6-E6 -> -0.44000092 | H6: 1.2 | I6: 0.692 | J6: °C
A7: Temperatura | B7: ERA5 | C7: MPI-ESM1-2-LR | D7: 23.450001 | E7: 23.65 | F7: =D7-E7 -> -0.19999924 | H7: 0.96 | I7: 0.913 | J7: °C
A8: Temperatura | B8: ERA5 | C8: MRI-ESM2-0 | D8: 23.889999 | E8: 23.65 | F8: =D8-E8 -> 0.23999939 | H8: 0.65 | I8: 0.839 | J8: °C
A9: Temperatura | B9: ERA5 | C9: NorESM2-MM | D9: 24.360001 | E9: 23.65 | F9: =D9-E9 -> 0.71000061 | H9: 0.89 | I9: 0.739 | J9: °C
A10: Temperatura | B10: ERA5 | C10: Ensamble | D10: 23.620001 | E10: 23.65 | F10: =D10-E10 -> -0.029999161 | H10: 0.61 | I10: 0.841 | J10: °C
A11: Temperatura | B11: IDEAM | C11: ACCESS-CM2 | D11: 23.190001 | E11: 26.11 | F11: =D11-E11 -> -2.9199995 | H11: 3 | I11: 0.759 | J11: °C
A12: Temperatura | B12: IDEAM | C12: GFDL-ESM4 | D12: 23.209999 | E12: 26.11 | F12: =D12-E12 -> -2.9000009 | H12: 3.12 | I12: 0.737 | J12: °C
A13: Temperatura | B13: IDEAM | C13: MPI-ESM1-2-LR | D13: 23.450001 | E13: 26.11 | F13: =D13-E13 -> -2.6599992 | H13: 2.87 | I13: 0.923 | J13: °C
A14: Temperatura | B14: IDEAM | C14: MRI-ESM2-0 | D14: 23.889999 | E14: 26.11 | F14: =D14-E14 -> -2.2200006 | H14: 2.3 | I14: 0.895 | J14: °C
A15: Temperatura | B15: IDEAM | C15: NorESM2-MM | D15: 24.360001 | E15: 26.11 | F15: =D15-E15 -> -1.7499994 | H15: 1.79 | I15: 0.819 | J15: °C
A16: Temperatura | B16: IDEAM | C16: Ensamble | D16: 23.620001 | E16: 26.11 | F16: =D16-E16 -> -2.4899992 | H16: 2.57 | I16: 0.885 | J16: °C
A17: Precipitación | B17: ERA5 | C17: ACCESS-CM2 | D17: 203.67 | E17: 219.03 | F17: =D17-E17 -> -15.36 | G17: =F17/E17 -> -0.07012738 | H17: 85.35 | I17: 0.754 | J17: mm/mes
A18: Precipitación | B18: ERA5 | C18: GFDL-ESM4 | D18: 163.76 | E18: 219.03 | F18: =D18-E18 -> -55.27 | G18: =F18/E18 -> -0.25233986 | H18: 98.63 | I18: 0.743 | J18: mm/mes
A19: Precipitación | B19: ERA5 | C19: MPI-ESM1-2-LR | D19: 127.59 | E19: 219.03 | F19: =D19-E19 -> -91.44 | G19: =F19/E19 -> -0.41747706 | H19: 115.04 | I19: 0.618 | J19: mm/mes
A20: Precipitación | B20: ERA5 | C20: MRI-ESM2-0 | D20: 201.44 | E20: 219.03 | F20: =D20-E20 -> -17.59 | G20: =F20/E20 -> -0.080308634 | H20: 66.71 | I20: 0.866 | J20: mm/mes
A21: Precipitación | B21: ERA5 | C21: NorESM2-MM | D21: 184.63 | E21: 219.03 | F21: =D21-E21 -> -34.4 | G21: =F21/E21 -> -0.15705611 | H21: 56.61 | I21: 0.938 | J21: mm/mes
A22: Precipitación | B22: ERA5 | C22: Ensamble | D22: 176.22 | E22: 219.03 | F22: =D22-E22 -> -42.81 | G22: =F22/E22 -> -0.19545268 | H22: 67.01 | I22: 0.865 | J22: mm/mes
A23: Precipitación | B23: CHIRPS | C23: ACCESS-CM2 | D23: 203.67 | E23: 226.33 | F23: =D23-E23 -> -22.66 | G23: =F23/E23 -> -0.10011929 | H23: 67.12 | I23: 0.869 | J23: mm/mes
A24: Precipitación | B24: CHIRPS | C24: GFDL-ESM4 | D24: 163.76 | E24: 226.33 | F24: =D24-E24 -> -62.57 | G24: =F24/E24 -> -0.27645473 | H24: 92.51 | I24: 0.829 | J24: mm/mes
A25: Precipitación | B25: CHIRPS | C25: MPI-ESM1-2-LR | D25: 127.59 | E25: 226.33 | F25: =D25-E25 -> -98.74 | G25: =F25/E25 -> -0.43626563 | H25: 124.31 | I25: 0.681 | J25: mm/mes
A26: Precipitación | B26: CHIRPS | C26: MRI-ESM2-0 | D26: 201.44 | E26: 226.33 | F26: =D26-E26 -> -24.89 | G26: =F26/E26 -> -0.10997216 | H26: 50.49 | I26: 0.938 | J26: mm/mes
A27: Precipitación | B27: CHIRPS | C27: NorESM2-MM | D27: 184.63 | E27: 226.33 | F27: =D27-E27 -> -41.7 | G27: =F27/E27 -> -0.18424425 | H27: 50.89 | I27: 0.969 | J27: mm/mes
A28: Precipitación | B28: CHIRPS | C28: Ensamble | D28: 176.22 | E28: 226.33 | F28: =D28-E28 -> -50.11 | G28: =F28/E28 -> -0.22140238 | H28: 60.33 | I28: 0.947 | J28: mm/mes
... A34: Precipitación | B34: IDEAM | C34: Ensamble | D34: 176.22 | E34: 253.73 | F34: =D34-E34 -> -77.51 | G34: =F34/E34 -> -0.30548221 | H34: 92.56 | I34: 0.921 | J34: mm/mes
A37: Climatología mensual 1995-2014 (media del ensamble de modelos y observaciones)
A38: Mes | B38: T modelos (°C) | C38: T ERA5 (°C) | D38: T IDEAM aprox. (°C) | E38: P modelos (mm/mes) | F38: P ERA5 (mm/mes) | G38: P CHIRPS (mm/mes) | H38: P IDEAM (mm/mes)
A39: Ene | B39: 23.92 | C39: 24.76 | D39: 26.75 | E39: 16.62 | F39: 65.92 | G39: 41 | H39: 33.63
A40: Feb | B40: 25.23 | C40: 25.12 | D40: 27.08 | E40: 27.94 | F40: 104.6 | G40: 79.41 | H40: 81.64
A41: Mar | B41: 25.75 | C41: 24.42 | D41: 26.83 | E41: 73.63 | F41: 201.8 | G41: 166.43 | H41: 195.67
A42: Abr | B42: 24.61 | C42: 23.69 | D42: 26.17 | E42: 193.29 | F42: 324.56 | G42: 320.68 | H42: 387
A43: May | B43: 23.08 | C43: 23.2 | D43: 25.77 | E43: 301.62 | F43: 351.74 | G43: 371.72 | H43: 441.55
A44: Jun | B44: 22.14 | C44: 22.61 | D44: 25.24 | E44: 295.79 | F44: 318.52 | G44: 352.63 | H44: 409
A45: Jul | B45: 21.98 | C45: 22.39 | D45: 25.11 | E45: 273.27 | F45: 285.53 | G45: 307 | H45: 328.34
A46: Ago | B46: 22.71 | C46: 22.89 | D46: 25.53 | E46: 233.96 | F46: 218.07 | G46: 256.86 | H46: 259.51
A47: Sep | B47: 23.57 | C47: 23.35 | D47: 25.97 | E47: 218.42 | F47: 202.2 | G47: 236 | H47: 266.32
A48: Oct | B48: 23.72 | C48: 23.7 | D48: 26.24 | E48: 247.69 | F48: 224.15 | G48: 260.4 | H48: 298.76
...

Sheet Proyección ajustada
A1: Proyecciones ajustadas con ERA5 (valores absolutos anuales por modelo)
A2: Temperatura: observado ERA5 + cambio del modelo. Precipitación: observado x factor trimestral móvil del modelo, renormalizado al cambio anual del modelo. Azul = entrada; negro = fórmula.
A4: Variable | B4: Referencia | C4: Escenario | D4: Plazo | E4: Observado 1995-2014 | F4: ACCESS-CM2 | G4: GFDL-ESM4 | H4: MPI-ESM1-2-LR | I4: MRI-ESM2-0 | J4: NorESM2-MM | K4: Media ensamble | L4: Mínimo | M4: Máximo | N4: Cambio vs observado | O4: Unidad anual
A5: Temperatura | B5: ERA5 | C5: SSP1-2.6 (bajas) | D5: Corto 2021-2040 | E5: 23.65 | F5: 24.82 | G5: 24.09 | H5: 24.23 | I5: 24.33 | J5: 24.46 | K5: =AVERAGE(F5:J5) -> 24.386 | L5: =MIN(F5:J5) -> 24.09 | M5: =MAX(F5:J5) -> 24.82 | N5: =K5-E5 -> 0.736 | O5: °C
A6: Temperatura | B6: ERA5 | C6: SSP1-2.6 (bajas) | D6: Mediano 2041-2060 | E6: 23.65 | F6: 25.38 | G6: 24.46 | H6: 24.57 | I6: 24.55 | J6: 24.61 | K6: =AVERAGE(F6:J6) -> 24.714 | L6: =MIN(F6:J6) -> 24.46 | M6: =MAX(F6:J6) -> 25.38 | N6: =K6-E6 -> 1.064 | O6: °C
A7: Temperatura | B7: ERA5 | C7: SSP1-2.6 (bajas) | D7: Largo 2081-2100 | E7: 23.65 | F7: 25.52 | G7: 24.33 | H7: 24.25 | I7: 24.71 | J7: 24.79 | K7: =AVERAGE(F7:J7) -> 24.72 | L7: =MIN(F7:J7) -> 24.25 | M7: =MAX(F7:J7) -> 25.52 | N7: =K7-E7 -> 1.07 | O7: °C
A8: Temperatura | B8: ERA5 | C8: SSP2-4.5 (medias) | D8: Corto 2021-2040 | E8: 23.65 | F8: 24.73 | G8: 24.21 | H8: 24.26 | I8: 24.44 | J8: 24.34 | K8: =AVERAGE(F8:J8) -> 24.396 | L8: =MIN(F8:J8) -> 24.21 | M8: =MAX(F8:J8) -> 24.73 | N8: =K8-E8 -> 0.746 | O8: °C
A9: Temperatura | B9: ERA5 | C9: SSP2-4.5 (medias) | D9: Mediano 2041-2060 | E9: 23.65 | F9: 25.79 | G9: 24.66 | H9: 24.84 | I9: 24.85 | J9: 25.06 | K9: =AVERAGE(F9:J9) -> 25.04 | L9: =MIN(F9:J9) -> 24.66 | M9: =MAX(F9:J9) -> 25.79 | N9: =K9-E9 -> 1.39 | O9: °C
A10: Temperatura | B10: ERA5 | C10: SSP2-4.5 (medias) | D10: Largo 2081-2100 | E10: 23.65 | F10: 26.84 | G10: 25.23 | H10: 25.67 | I10: 25.63 | J10: 25.56 | K10: =AVERAGE(F10:J10) -> 25.786 | L10: =MIN(F10:J10) -> 25.23 | M10: =MAX(F10:J10) -> 26.84 | N10: =K10-E10 -> 2.136 | O10: °C
A11: Temperatura | B11: ERA5 | C11: SSP5-8.5 (altas) | D11: Corto 2021-2040 | E11: 23.65 | F11: 24.82 | G11: 24.24 | H11: 24.62 | I11: 24.52 | J11: 24.52 | K11: =AVERAGE(F11:J11) -> 24.544 | L11: =MIN(F11:J11) -> 24.24 | M11: =MAX(F11:J11) -> 24.82 | N11: =K11-E11 -> 0.894 | O11: °C
A12: Temperatura | B12: ERA5 | C12: SSP5-8.5 (altas) | D12: Mediano 2041-2060 | E12: 23.65 | F12: 26.19 | G12: 25.11 | H12: 25.68 | I12: 25.38 | J12: 25.35 | K12: =AVERAGE(F12:J12) -> 25.542 | L12: =MIN(F12:J12) -> 25.11 | M12: =MAX(F12:J12) -> 26.19 | N12: =K12-E12 -> 1.892 | O12: °C
A13: Temperatura | B13: ERA5 | C13: SSP5-8.5 (altas) | D13: Largo 2081-2100 | E13: 23.65 | F13: 29.79 | G13: 27.82 | H13: 28.35 | I13: 27.5 | J13: 27.67 | K13: =AVERAGE(F13:J13) -> 28.226 | L13: =MIN(F13:J13) -> 27.5 | M13: =MAX(F13:J13) -> 29.79 | N13: =K13-E13 -> 4.576 | O13: °C
A14: Precipitación | B14: ERA5 | C14: SSP1-2.6 (bajas) | D14: Corto 2021-2040 | E14: 2628.32 | F14: 2774.6 | G14: 2647.12 | H14: 2600.98 | I14: 2720 | J14: 2491.4 | K14: =AVERAGE(F14:J14) -> 2646.82 | L14: =MIN(F14:J14) -> 2491.4 | M14: =MAX(F14:J14) -> 2774.6 | N14: =K14/E14-1 -> 0.0070387167 | O14: mm/año
A15: Precipitación | B15: ERA5 | C15: SSP1-2.6 (bajas) | D15: Mediano 2041-2060 | E15: 2628.32 | F15: 2970.83 | G15: 2512.64 | H15: 2548.37 | I15: 2772.72 | J15: 2601.62 | K15: =AVERAGE(F15:J15) -> 2681.236 | L15: =MIN(F15:J15) -> 2512.64 | M15: =MAX(F15:J15) -> 2970.83 | N15: =K15/E15-1 -> 0.020133013 | O15: mm/año
A16: Precipitación | B16: ERA5 | C16: SSP1-2.6 (bajas) | D16: Largo 2081-2100 | E16: 2628.32 | F16: 2978.85 | G16: 2623.19 | H16: 2595.74 | I16: 2749.99 | J16: 2467.29 | K16: =AVERAGE(F16:J16) -> 2683.012 | L16: =MIN(F16:J16) -> 2467.29 | M16: =MAX(F16:J16) -> 2978.85 | N16: =K16/E16-1 -> 0.02080873 | O16: mm/año
A17: Precipitación | B17: ERA5 | C17: SSP2-4.5 (medias) | D17: Corto 2021-2040 | E17: 2628.32 | F17: 2823.85 | G17: 2520.33 | H17: 2595.12 | I17: 2628.72 | J17: 2615.96 | K17: =AVERAGE(F17:J17) -> 2636.796 | L17: =MIN(F17:J17) -> 2520.33 | M17: =MAX(F17:J17) -> 2823.85 | N17: =K17/E17-1 -> 0.0032248737 | O17: mm/año
A18: Precipitación | B18: ERA5 | C18: SSP2-4.5 (medias) | D18: Mediano 2041-2060 | E18: 2628.32 | F18: 2769.24 | G18: 2575.18 | H18: 2618.33 | I18: 2725.93 | J18: 2459.33 | K18: =AVERAGE(F18:J18) -> 2629.602 | L18: =MIN(F18:J18) -> 2459.33 | M18: =MAX(F18:J18) -> 2769.24 | N18: =K18/E18-1 -> 0.00048776405 | O18: mm/año
A19: Precipitación | B19: ERA5 | C19: SSP2-4.5 (medias) | D19: Largo 2081-2100 | E19: 2628.32 | F19: 2998.43 | G19: 2539.74 | H19: 2499.98 | I19: 2646.25 | J19: 2515.6 | K19: =AVERAGE(F19:J19) -> 2640 | L19: =MIN(F19:J19) -> 2499.98 | M19: =MAX(F19:J19) -> 2998.43 | N19: =K19/E19-1 -> 0.0044439033 | O19: mm/año
A20: Precipitación | B20: ERA5 | C20: SSP5-8.5 (altas) | D20: Corto 2021-2040 | E20: 2628.32 | F20: 2795.56 | G20: 2484.67 | H20: 2505.89 | I20: 2631.56 | J20: 2543.44 | K20: =AVERAGE(F20:J20) -> 2592.224 | L20: =MIN(F20:J20) -> 2484.67 | M20: =MAX(F20:J20) -> 2795.56 | N20: =K20/E20-1 -> -0.013733488 | O20: mm/año
A21: Precipitación | B21: ERA5 | C21: SSP5-8.5 (altas) | D21: Mediano 2041-2060 | E21: 2628.32 | F21: 2578.56 | G21: 2432.86 | H21: 2389.35 | I21: 2649.79 | J21: 2564.76 | K21: =AVERAGE(F21:J21) -> 2523.064 | L21: =MIN(F21:J21) -> 2389.35 | M21: =MAX(F21:J21) -> 2649.79 | N21: =K21/E21-1 -> -0.040046874 | O21: mm/año
A22: Precipitación | B22: ERA5 | C22: SSP5-8.5 (altas) | D22: Largo 2081-2100 | E22: 2628.32 | F22: 2481.84 | G22: 2147.85 | H22: 2262.78 | I22: 2726.34 | J22: 2517.21 | K22: =AVERAGE(F22:J22) -> 2427.204 | L22: =MIN(F22:J22) -> 2147.85 | M22: =MAX(F22:J22) -> 2726.34 | N22: =K22/E22-1 -> -0.076518841 | O22: mm/año
A23: Precipitación | B23: CHIRPS | C23: SSP1-2.6 (bajas) | D23: Corto 2021-2040 | E23: 2716 | F23: 2867.16 | G23: 2735.44 | H23: 2687.75 | I23: 2810.74 | J23: 2574.51 | K23: =AVERAGE(F23:J23) -> 2735.12 | L23: =MIN(F23:J23) -> 2574.51 | M23: =MAX(F23:J23) -> 2867.16 | N23: =K23/E23-1 -> 0.0070397644 | O23: mm/año
A24: Precipitación | B24: CHIRPS | C24: SSP1-2.6 (bajas) | D24: Mediano 2041-2060 | E24: 2716 | F24: 3069.94 | G24: 2596.46 | H24: 2633.39 | I24: 2865.22 | J24: 2688.41 | K24: =AVERAGE(F24:J24) -> 2770.684 | L24: =MIN(F24:J24) -> 2596.46 | M24: =MAX(F24:J24) -> 3069.94 | N24: =K24/E24-1 -> 0.020134021 | O24: mm/año
A25: Precipitación | B25: CHIRPS | C25: SSP1-2.6 (bajas) | D25: Largo 2081-2100 | E25: 2716 | F25: 3078.23 | G25: 2710.7 | H25: 2682.34 | I25: 2841.73 | J25: 2549.61 | K25: =AVERAGE(F25:J25) -> 2772.522 | L25: =MIN(F25:J25) -> 2549.61 | M25: =MAX(F25:J25) -> 3078.23 | N25: =K25/E25-1 -> 0.020810751 | O25: mm/año
... A31: Precipitación | B31: CHIRPS | C31: SSP5-8.5 (altas) | D31: Largo 2081-2100 | E31: 2716 | F31: 2564.63 | G31: 2219.5 | H31: 2338.27 | I31: 2817.3 | J31: 2601.19 | K31: =AVERAGE(F31:J31) -> 2508.178 | L31: =MIN(F31:J31) -> 2219.5 | M31: =MAX(F31:J31) -> 2817.3 | N31: =K31/E31-1 -> -0.076517673 | O31: mm/año
A34: Matrices para los gráficos (referencia ERA5)
A35: Temperatura media anual (°C), ERA5
A36: Plazo | B36: SSP1-2.6 (bajas) | C36: SSP2-4.5 (medias) | D36: SSP5-8.5 (altas)
A37: Observado 1995-2014 | B37: =$E$5 -> 23.65 | C37: =$E$5 -> 23.65 | D37: =$E$5 -> 23.65
A38: Corto 2021-2040 | B38: =K5 -> 24.386 | C38: =K8 -> 24.396 | D38: =K11 -> 24.544
A39: Mediano 2041-2060 | B39: =K6 -> 24.714 | C39: =K9 -> 25.04 | D39: =K12 -> 25.542
A40: Largo 2081-2100 | B40: =K7 -> 24.72 | C40: =K10 -> 25.786 | D40: =K13 -> 28.226
A42: Precipitación anual (mm/año), ERA5
A43: Plazo | B43: SSP1-2.6 (bajas) | C43: SSP2-4.5 (medias) | D43: SSP5-8.5 (altas)
A44: Observado 1995-2014 | B44: =$E$14 -> 2628.32 | C44: =$E$14 -> 2628.32 | D44: =$E$14 -> 2628.32
A45: Corto 2021-2040 | B45: =K14 -> 2646.82 | C45: =K17 -> 2636.796 | D45: =K20 -> 2592.224
A46: Mediano 2041-2060 | B46: =K15 -> 2681.236 | C46: =K18 -> 2629.602 | D46: =K21 -> 2523.064
A47: Largo 2081-2100 | B47: =K16 -> 2683.012 | C47: =K19 -> 2640 | D47: =K22 -> 2427.204

Sheet Proy. ajustada mensual
A1: Proyecciones ajustadas con ERA5 y CHIRPS: valores mensuales (media del ensamble y rango entre modelos)
A2: Valores calculados en Python (ver Metodología). Usa el filtro de la fila 4 para escoger variable, referencia, escenario o plazo.
A4: Variable | B4: Referencia | C4: Escenario | D4: Plazo | E4: Mes | F4: Observado 1995-2014 | G4: Media ensamble | H4: Mínimo | I4: Máximo | J4: Unidad
A5: Temperatura | B5: ERA5 | C5: SSP1-2.6 (bajas) | D5: Corto 2021-2040 | E5: Ene | F5: 24.76 | G5: 25.45 | H5: 25.17 | I5: 25.87 | J5: °C
A6: Temperatura | B6: ERA5 | C6: SSP1-2.6 (bajas) | D6: Corto 2021-2040 | E6: Feb | F6: 25.12 | G6: 26.01 | H6: 25.65 | I6: 26.72 | J6: °C
A7: Temperatura | B7: ERA5 | C7: SSP1-2.6 (bajas) | D7: Corto 2021-2040 | E7: Mar | F7: 24.42 | G7: 25.38 | H7: 25.09 | I7: 25.79 | J7: °C
A8: Temperatura | B8: ERA5 | C8: SSP1-2.6 (bajas) | D8: Corto 2021-2040 | E8: Abr | F8: 23.69 | G8: 24.3 | H8: 23.86 | I8: 24.62 | J8: °C
A9: Temperatura | B9: ERA5 | C9: SSP1-2.6 (bajas) | D9: Corto 2021-2040 | E9: May | F9: 23.2 | G9: 23.85 | H9: 23.41 | I9: 24.25 | J9: °C
A10: Temperatura | B10: ERA5 | C10: SSP1-2.6 (bajas) | D10: Corto 2021-2040 | E10: Jun | F10: 22.61 | G10: 23.36 | H10: 23.04 | I10: 23.74 | J10: °C
A11: Temperatura | B11: ERA5 | C11: SSP1-2.6 (bajas) | D11: Corto 2021-2040 | E11: Jul | F11: 22.39 | G11: 23.03 | H11: 22.79 | I11: 23.46 | J11: °C
A12: Temperatura | B12: ERA5 | C12: SSP1-2.6 (bajas) | D12: Corto 2021-2040 | E12: Ago | F12: 22.89 | G12: 23.59 | H12: 23.26 | I12: 23.99 | J12: °C
A13: Temperatura | B13: ERA5 | C13: SSP1-2.6 (bajas) | D13: Corto 2021-2040 | E13: Sep | F13: 23.35 | G13: 24.12 | H13: 23.74 | I13: 24.46 | J13: °C
A14: Temperatura | B14: ERA5 | C14: SSP1-2.6 (bajas) | D14: Corto 2021-2040 | E14: Oct | F14: 23.7 | G14: 24.41 | H14: 24.15 | I14: 24.89 | J14: °C
A15: Temperatura | B15: ERA5 | C15: SSP1-2.6 (bajas) | D15: Corto 2021-2040 | E15: Nov | F15: 23.76 | G15: 24.43 | H15: 24.1 | I15: 24.95 | J15: °C
A16: Temperatura | B16: ERA5 | C16: SSP1-2.6 (bajas) | D16: Corto 2021-2040 | E16: Dic | F16: 23.95 | G16: 24.71 | H16: 24.41 | I16: 25.09 | J16: °C
... A328: Precipitación | B328: CHIRPS | C328: SSP5-8.5 (altas) | D328: Largo 2081-2100 | E328: Dic | F328: 111.78 | G328: 104.26 | H328: 60.08 | I328: 146.41 | J328: mm/mes

Sheet Sensibilidad precip.
A1: Sensibilidad del método de ajuste de la precipitación (cambio anual, media del ensamble, base ERA5)
A2: El factor puramente mensual infla el cambio anual porque en los meses secos el modelo parte de una base casi nula.
A4: Escenario | B4: Plazo | C4: a) Factor mensual | D4: b) Factor trimestral móvil | E4: c) Factor anual (= cambio del modelo) | F4: Adoptado: trimestral renormalizado | G4: Inflación del mensual (puntos)
A5: SSP1-2.6 (bajas) | B5: Corto 2021-2040 | C5: 0.038 | D5: 0.027 | E5: 0.007 | F5: =E5 -> 0.007 | G5: =(C5-F5)*100 -> 3.1
A6: SSP1-2.6 (bajas) | B6: Mediano 2041-2060 | C6: 0.059 | D6: 0.042 | E6: 0.02 | F6: =E6 -> 0.02 | G6: =(C6-F6)*100 -> 3.9
A7: SSP1-2.6 (bajas) | B7: Largo 2081-2100 | C7: 0.053 | D7: 0.037 | E7: 0.021 | F7: =E7 -> 0.021 | G7: =(C7-F7)*100 -> 3.2
A8: SSP2-4.5 (medias) | B8: Corto 2021-2040 | C8: 0.038 | D8: 0.018 | E8: 0.003 | F8: =E8 -> 0.003 | G8: =(C8-F8)*100 -> 3.5
A9: SSP2-4.5 (medias) | B9: Mediano 2041-2060 | C9: 0.015 | D9: 0.004 | E9: 0 | F9: =E9 -> 0 | G9: =(C9-F9)*100 -> 1.5
A10: SSP2-4.5 (medias) | B10: Largo 2081-2100 | C10: 0.067 | D10: 0.038 | E10: 0.004 | F10: =E10 -> 0.004 | G10: =(C10-F10)*100 -> 6.3
A11: SSP5-8.5 (altas) | B11: Corto 2021-2040 | C11: 0.014 | D11: 0.002 | E11: -0.014 | F11: =E11 -> -0.014 | G11: =(C11-F11)*100 -> 2.8
A12: SSP5-8.5 (altas) | B12: Mediano 2041-2060 | C12: -0.006 | D12: -0.023 | E12: -0.04 | F12: =E12 -> -0.04 | G12: =(C12-F12)*100 -> 3.4
A13: SSP5-8.5 (altas) | B13: Largo 2081-2100 | C13: -0.029 | D13: -0.05 | E13: -0.077 | F13: =E13 -> -0.077 | G13: =(C13-F13)*100 -> 4.8
A15: Se adopta (f): el total anual cambia exactamente lo que cambia cada modelo; el factor trimestral solo redistribuye entre meses.

Sheet ENSO (ONI)
A1: ENSO (ONI): efecto histórico sobre el Meta y comparación con el cambio climático
A2: Regresión mensual 1995-2025: anomalía ~ tendencia + ONI con rezago (errores Newey-West). Azul = entrada; negro = fórmula; fondo amarillo = supuesto editable.
A4: 1. Efecto histórico del ENSO (por cada 1 °C de ONI)
A5: Variable | B5: Rezago (meses) | C5: Correlación (sin tendencia) | D5: Efecto por 1 °C de ONI | E5: Error (Newey-West) | F5: t | G5: Tendencia por década | H5: Unidad | I5: ¿|t| > 2?
A6: T ERA5 (°C) | B6: 3 | C6: 0.49 | D6: 0.254 | E6: 0.036 | F6: 7.1 | G6: 0.335 | H6: °C por °C de ONI | I6: =IF(ABS(F6)>2,"Sí","No") -> Sí
A7: T IDEAM aprox. (°C) | B7: 3 | C7: 0.59 | D7: 0.294 | E7: 0.031 | F7: 9.5 | G7: 0.195 | H7: °C por °C de ONI | I7: =IF(ABS(F7)>2,"Sí","No") -> Sí
A8: P ERA5 (%) | B8: 1 | C8: -0.19 | D8: -6.313 | E8: 1.694 | F8: -3.7 | G8: -5.69 | H8: % por °C de ONI | I8: =IF(ABS(F8)>2,"Sí","No") -> Sí
A9: P CHIRPS (%) | B9: 1 | C9: -0.11 | D9: -4.318 | E9: 1.945 | F9: -2.2 | G9: 1.405 | H9: % por °C de ONI | I9: =IF(ABS(F9)>2,"Sí","No") -> Sí
A10: P IDEAM (%) | B10: 1 | C10: -0.07 | D10: -3.815 | E10: 2.844 | F10: -1.3 | G10: 4.281 | H10: % por °C de ONI | I10: =IF(ABS(F10)>2,"Sí","No") -> No
A12: 2. Supuestos de un año con ENSO sostenido (editables)
A13: ONI sostenido, El Niño fuerte (°C) | B13: 1.5
A14: ONI sostenido, La Niña (°C) | B14: -1
A15: Efecto en T anual, El Niño fuerte (°C) | B15: =D6*B13 -> 0.381
A16: Efecto en T anual, La Niña (°C) | B16: =D6*B14 -> -0.254
A17: Incertidumbre del efecto El Niño (± °C, 1,96 x error) | B17: =1.96*E6*B13 -> 0.10584
A18: Referencia: 2015 tuvo ONI medio +1,55 (El Niño fuerte). El efecto usa la regresión de T ERA5 (fila 6) y supone que la relación y la amplitud del ENSO no cambian.
A20: 3. Temperatura anual proyectada con efecto ENSO (ERA5, media del ensamble)
A21: Escenario | B21: Plazo | C21: Cambio climático vs 1995-2014 (°C) | D21: T proyectada, año neutro (°C) | E21: T en año El Niño fuerte (°C) | F21: T en año La Niña (°C) | G21: Etiqueta
A22: ='Proyección ajustada'!C5 -> SSP1-2.6 (bajas) | B22: ='Proyección ajustada'!D5 -> Corto 2021-2040 | C22: ='Proyección ajustada'!N5 -> 0.736 | D22: ='Proyección ajustada'!K5 -> 24.386 | E22: =D22+$B$15 -> 24.767 | F22: =D22+$B$16 -> 24.132 | G22: =LEFT(A22,FIND(" ",A22)-1)&" "&LEFT(B22,FIND(" ",B22)-1) -> SSP1-2.6 Corto
A23: ='Proyección ajustada'!C6 -> SSP1-2.6 (bajas) | B23: ='Proyección ajustada'!D6 -> Mediano 2041-2060 | C23: ='Proyección ajustada'!N6 -> 1.064 | D23: ='Proyección ajustada'!K6 -> 24.714 | E23: =D23+$B$15 -> 25.095 | F23: =D23+$B$16 -> 24.46 | G23: =LEFT(A23,FIND(" ",A23)-1)&" "&LEFT(B23,FIND(" ",B23)-1) -> SSP1-2.6 Mediano
A24: ='Proyección ajustada'!C7 -> SSP1-2.6 (bajas) | B24: ='Proyección ajustada'!D7 -> Largo 2081-2100 | C24: ='Proyección ajustada'!N7 -> 1.07 | D24: ='Proyección ajustada'!K7 -> 24.72 | E24: =D24+$B$15 -> 25.101 | F24: =D24+$B$16 -> 24.466 | G24: =LEFT(A24,FIND(" ",A24)-1)&" "&LEFT(B24,FIND(" ",B24)-1) -> SSP1-2.6 Largo
A25: ='Proyección ajustada'!C8 -> SSP2-4.5 (medias) | B25: ='Proyección ajustada'!D8 -> Corto 2021-2040 | C25: ='Proyección ajustada'!N8 -> 0.746 | D25: ='Proyección ajustada'!K8 -> 24.396 | E25: =D25+$B$15 -> 24.777 | F25: =D25+$B$16 -> 24.142 | G25: =LEFT(A25,FIND(" ",A25)-1)&" "&LEFT(B25,FIND(" ",B25)-1) -> SSP2-4.5 Corto
A26: ='Proyección ajustada'!C9 -> SSP2-4.5 (medias) | B26: ='Proyección ajustada'!D9 -> Mediano 2041-2060 | C26: ='Proyección ajustada'!N9 -> 1.39 | D26: ='Proyección ajustada'!K9 -> 25.04 | E26: =D26+$B$15 -> 25.421 | F26: =D26+$B$16 -> 24.786 | G26: =LEFT(A26,FIND(" ",A26)-1)&" "&LEFT(B26,FIND(" ",B26)-1) -> SSP2-4.5 Mediano
A27: ='Proyección ajustada'!C10 -> SSP2-4.5 (medias) | B27: ='Proyección ajustada'!D10 -> Largo 2081-2100 | C27: ='Proyección ajustada'!N10 -> 2.136 | D27: ='Proyección ajustada'!K10 -> 25.786 | E27: =D27+$B$15 -> 26.167 | F27: =D27+$B$16 -> 25.532 | G27: =LEFT(A27,FIND(" ",A27)-1)&" "&LEFT(B27,FIND(" ",B27)-1) -> SSP2-4.5 Largo
A28: ='Proyección ajustada'!C11 -> SSP5-8.5 (altas) | B28: ='Proyección ajustada'!D11 -> Corto 2021-2040 | C28: ='Proyección ajustada'!N11 -> 0.894 | D28: ='Proyección ajustada'!K11 -> 24.544 | E28: =D28+$B$15 -> 24.925 | F28: =D28+$B$16 -> 24.29 | G28: =LEFT(A28,FIND(" ",A28)-1)&" "&LEFT(B28,FIND(" ",B28)-1) -> SSP5-8.5 Corto
